Workbook
Name IQ_CH: 110000
Name IQ_CQ: 5000
Name IQ_CY: 10000
Name IQ_DAILY: 500000
Name IQ_FH: 100000
Name IQ_FQ: 500
Name IQ_FY: 1000
Name IQ_LTM: 2000
Name IQ_MONTH: 15000
Name IQ_NTM: 6000
Name IQ_WEEK: 50000
Name IQ_YTD: 3000
Name UPDATE: '[1]Data Sheet'!$E$1
Name UPDATE: #REF!
Name UPDATE: 'Data Sheet'!$E$1

Sheet Quarters
A1: ='Profit & Loss'!A1 -> NTPC LTD | E1: =UPDATE | J1: SCREENER.IN
A3: Narration | B3: ='Data Sheet'!B42 -> 44834 | C3: ='Data Sheet'!C42 -> 44926 | D3: ='Data Sheet'!D42 -> 45016 | E3: ='Data Sheet'!E42 -> 45107 | F3: ='Data Sheet'!F42 -> 45199 | G3: ='Data Sheet'!G42 -> 45291 | H3: ='Data Sheet'!H42 -> 45382 | I3: ='Data Sheet'!I42 -> 45473 | ... K3: ='Data Sheet'!K42 -> 45657
A4: Sales | B4: ='Data Sheet'!B43 -> 44175.03 | C4: ='Data Sheet'!C43 -> 44601.84 | D4: ='Data Sheet'!D43 -> 44252.92 | E4: ='Data Sheet'!E43 -> 43075.09 | F4: ='Data Sheet'!F43 -> 44983.35 | G4: ='Data Sheet'!G43 -> 42820.38 | H4: ='Data Sheet'!H43 -> 47622.06 | I4: ='Data Sheet'!I43 -> 48520.57 | ... K4: ='Data Sheet'!K43 -> 45052.82
A5: Expenses | B5: ='Data Sheet'!B44 -> 33808.14 | C5: ='Data Sheet'!C44 -> 31782.94 | D5: ='Data Sheet'!D44 -> 32310.52 | E5: ='Data Sheet'!E44 -> 30664.22 | F5: ='Data Sheet'!F44 -> 32303.16 | G5: ='Data Sheet'!G44 -> 31458.23 | H5: ='Data Sheet'!H44 -> 33638.23 | I5: ='Data Sheet'!I44 -> 35091.26 | ... K5: ='Data Sheet'!K44 -> 31728.79
A6: Operating Profit | B6: ='Data Sheet'!B51 -> 10366.89 | C6: ='Data Sheet'!C51 -> 12818.9 | D6: ='Data Sheet'!D51 -> 11942.4 | E6: ='Data Sheet'!E51 -> 12410.87 | F6: ='Data Sheet'!F51 -> 12680.19 | G6: ='Data Sheet'!G51 -> 11362.15 | H6: ='Data Sheet'!H51 -> 13983.83 | I6: ='Data Sheet'!I51 -> 13429.31 | ... K6: ='Data Sheet'!K51 -> 13324.03
A7: Other Income | B7: ='Data Sheet'!B45 -> 1380.15 | C7: ='Data Sheet'!C45 -> 747.49 | D7: ='Data Sheet'!D45 -> 1083.88 | E7: ='Data Sheet'!E45 -> 994.05 | F7: ='Data Sheet'!F45 -> 1024.05 | G7: ='Data Sheet'!G45 -> 2532.46 | H7: ='Data Sheet'!H45 -> 1405.89 | I7: ='Data Sheet'!I45 -> 1195.07 | ... K7: ='Data Sheet'!K45 -> 1002.62
A8: Depreciation | B8: ='Data Sheet'!B46 -> 3687.23 | C8: ='Data Sheet'!C46 -> 3715.08 | D8: ='Data Sheet'!D46 -> 3848.46 | E8: ='Data Sheet'!E46 -> 3821.28 | F8: ='Data Sheet'!F46 -> 4037.68 | G8: ='Data Sheet'!G46 -> 4073.91 | H8: ='Data Sheet'!H46 -> 4270.76 | I8: ='Data Sheet'!I46 -> 4204.2 | ... K8: ='Data Sheet'!K46 -> 4318.3
A9: Interest | B9: ='Data Sheet'!B47 -> 2651.54 | C9: ='Data Sheet'!C47 -> 3168.18 | D9: ='Data Sheet'!D47 -> 2859.54 | E9: ='Data Sheet'!E47 -> 2922.37 | F9: ='Data Sheet'!F47 -> 2920.51 | G9: ='Data Sheet'!G47 -> 3250.08 | H9: ='Data Sheet'!H47 -> 2955.25 | I9: ='Data Sheet'!I47 -> 3135.91 | ... K9: ='Data Sheet'!K47 -> 2763.54
A10: Profit before tax | B10: ='Data Sheet'!B48 -> 5408.27 | C10: ='Data Sheet'!C48 -> 6683.13 | D10: ='Data Sheet'!D48 -> 6318.28 | E10: ='Data Sheet'!E48 -> 6661.27 | F10: ='Data Sheet'!F48 -> 6746.05 | G10: ='Data Sheet'!G48 -> 6570.62 | H10: ='Data Sheet'!H48 -> 8163.71 | I10: ='Data Sheet'!I48 -> 7284.27 | ... K10: ='Data Sheet'!K48 -> 7244.81
A11: Tax | B11: ='Data Sheet'!B49 -> 1990.6 | C11: ='Data Sheet'!C49 -> 1828.77 | D11: ='Data Sheet'!D49 -> 1446.73 | E11: ='Data Sheet'!E49 -> 1754.14 | F11: ='Data Sheet'!F49 -> 2019.65 | G11: ='Data Sheet'!G49 -> 1361.75 | H11: ='Data Sheet'!H49 -> 1673.66 | I11: ='Data Sheet'!I49 -> 1778.2 | ... K11: ='Data Sheet'!K49 -> 2075.12
A12: Net profit | B12: ='Data Sheet'!B50 -> 3338.45 | C12: ='Data Sheet'!C50 -> 4776.61 | D12: ='Data Sheet'!D50 -> 4860.67 | E12: ='Data Sheet'!E50 -> 4873.24 | F12: ='Data Sheet'!F50 -> 4614.64 | G12: ='Data Sheet'!G50 -> 5155.28 | H12: ='Data Sheet'!H50 -> 6168.73 | I12: ='Data Sheet'!I50 -> 5474.14 | ... K12: ='Data Sheet'!K50 -> 5062.51
A14: OPM | B14: =IF(B4>0,B6/B4,"") -> 0.2346776 | C14: =IF(C4>0,C6/C4,"") -> 0.28740743 | D14: =IF(D4>0,D6/D4,"") -> 0.26986694 | E14: =IF(E4>0,E6/E4,"") -> 0.28812174 | F14: =IF(F4>0,F6/F4,"") -> 0.2818863 | G14: =IF(G4>0,G6/G4,"") -> 0.26534445 | H14: =IF(H4>0,H6/H4,"") -> 0.29364185 | I14: =IF(I4>0,I6/I4,"") -> 0.2767756 | ... K14: =IF(K4>0,K6/K4,"") -> 0.29574242

Sheet Cash Flow Statement
C2: 41334 | D2: 41699 | E2: 42064 | F2: 42430 | G2: 42795 | H2: 43160 | I2: 43525 | J2: 43891 | K2: 44256 | L2: 44621 | M2: 44986 | N2: 45352
B3: Cash from Operating Activity - | C3: 22163 | D3: 36151 | E3: 35531 | F3: 37900 | G3: 30199 | H3: 23857 | I3: 18891 | J3: 26633 | K3: 29001 | L3: 14283 | M3: 35388 | N3: 67915
B4: Profit from operations | C4: 24406 | D4: 36303 | E4: 43397 | F4: 38626 | G4: 28840 | H4: 33312 | I4: 28771 | J4: 23352 | K4: 31198 | L4: 26943 | M4: 41694 | N4: 65106
B5: Receivables | C5: -5177 | D5: 445 | E5: -3179 | F5: -2223 | G5: -4152 | H5: -10688 | I5: -9109 | J5: 9950 | K5: -5505 | L5: 185 | M5: -2213 | N5: -1875
B6: Inventory | C6: -2656 | D6: -2853 | E6: -3692 | F6: -5743 | G6: -6621 | H6: -3560 | I6: 2069 | J6: 2326 | K6: 3814 | L6: 472 | M6: -5665 | N6: -7265
B7: Payables | C7: 8132 | D7: 4694 | E7: 3598 | F7: 3947 | G7: 9301 | H7: 7320 | I7: -4692 | J7: -8085 | K7: 5748 | L7: -7012 | M7: 6945 | N7: 13706
B8: Loans Advances | C8: 0 | D8: 0 | E8: 0 | F8: -520 | G8: 0 | H8: 0 | I8: 0 | J8: 0 | K8: 0 | L8: 0 | M8: 0 | N8: 0
B9: Other WC items | C9: -303 | D9: 1870 | E9: -398 | F9: 5852 | G9: 4727 | H9: 494 | I9: 4512 | J9: 875 | K9: -4150 | L9: -4396 | M9: -2194 | N9: 2760
B10: Working capital changes | C10: -3 | D10: 4157 | E10: -3672 | F10: 1313 | G10: 3254 | H10: -6434 | I10: -7221 | J10: 5065 | K10: -93 | L10: -10750 | M10: -3127 | N10: 7325
B11: Direct taxes | C11: -2240 | D11: -4308 | E11: -4194 | F11: -2040 | G11: -1895 | H11: -3021 | I11: -2659 | J11: -1785 | K11: -2105 | L11: -1910 | M11: -3179 | N11: -4516
B12: Cash from Investing Activity - | C12: -22969 | D12: -27991 | E12: -36232 | F12: -36694 | G12: -39571 | H12: -25139 | I12: -20878 | J12: -33115 | K12: -25672 | L12: -4444 | M12: -15417 | N12: -22782
B13: Fixed assets purchased | C13: -18863 | D13: -26975 | E13: -31962 | F13: -31503 | G13: -16072 | H13: -35079 | I13: -35304 | J13: -29702 | K13: -20205 | L13: -15168 | M13: -19230 | N13: -31414
B14: Fixed assets sold | C14: 37 | D14: 50 | E14: 74 | F14: 59 | G14: 53 | H14: 30 | I14: 67 | J14: 171 | K14: 351 | L14: 230 | M14: 285 | N14: 231
... B33: Net Cash Flow | C33: -2499 | D33: 4277 | E33: 4500 | F33: -2589 | G33: -3167 | H33: 730 | I33: 6843 | J33: -3092 | K33: 13232 | L33: 6459 | M33: -6272 | N33: 8128

Sheet Company Profile
B2: ='Data Sheet'!B1 & " - " & "One Page Profile" -> NTPC LTD - One Page Profile
C4: ='Input Sheet'!C3 -> NTPC (National Thermal Power Corporation) Ltd along with its subsidiaries/ associates & JVs is primarily involved in generation and sale of bulk power to State power utilities. Other business of the group includes providing consultancy, project management & supervision, energy trading, oil & gas exploration and coal mining.
B5: INR (Crs.)
B6: Key Financial Matrix | C6: ='Data Sheet'!G16 -> 43921 | D6: ='Data Sheet'!H16 -> 44286 | E6: ='Data Sheet'!I16 -> 44651 | F6: ='Data Sheet'!J16 -> 45016 | G6: ='Data Sheet'!K16 -> 45382 | I6: Share Price - 5Y
B8: Total Sales | C8: ='Data Sheet'!G17 -> 109464.04 | D8: ='Data Sheet'!H17 -> 111531.15 | E8: ='Data Sheet'!I17 -> 132669.28 | F8: ='Data Sheet'!J17 -> 176207.18 | G8: ='Data Sheet'!K17 -> 178500.88
B9: Sales Growth (YoY) | C9: =HistoricalFS!H11 -> 0.091512779 | D9: =HistoricalFS!I11 -> 0.018883918 | E9: =HistoricalFS!J11 -> 0.18952669 | F9: =HistoricalFS!K11 -> 0.32816866 | G9: =HistoricalFS!L11 -> 0.013017063
B10: Gross Profit Margins (%) | C10: =HistoricalFS!H17 -> 0.30917934 | D10: =HistoricalFS!I17 -> 0.32654115 | E10: =HistoricalFS!J17 -> 0.31238196 | F10: =HistoricalFS!K17 -> 0.29075058 | G10: =HistoricalFS!L17 -> 0.29324113
B11: EBITDA Margins (%) | C11: =HistoricalFS!H23 -> 0.28854892 | D11: =HistoricalFS!I23 -> 0.30523957 | E11: =HistoricalFS!J23 -> 0.30422959 | F11: =HistoricalFS!K23 -> 0.27011357 | G11: =HistoricalFS!L23 -> 0.28826575
B12: EBIT Margins (%) | C12: =HistoricalFS!H32 -> 0.11913099 | D12: =HistoricalFS!I32 -> 0.11090355 | E12: =HistoricalFS!J32 -> 0.1296337 | F12: =HistoricalFS!K32 -> 0.12120125 | G12: =HistoricalFS!L32 -> 0.12857948
B13: Net Margins (%) | C13: =HistoricalFS!H38 -> 0.033737289 | D13: =HistoricalFS!I38 -> 0.08920082 | E13: =HistoricalFS!J38 -> 0.091590985 | F13: =HistoricalFS!K38 -> 0.082632331 | G13: =HistoricalFS!L38 -> 0.090432888
B14: Earinings Per Share (In Rs.) | C14: =HistoricalFS!H42 -> 3.7323591 | D14: =HistoricalFS!I42 -> 10.259851 | E14: =HistoricalFS!J42 -> 12.531387 | F14: =HistoricalFS!K42 -> 15.01584 | G14: =HistoricalFS!L42 -> 16.647261
B15: EPS Growth (YoY) | C15: =HistoricalFS!H43 -> -0.67075494 | D15: =HistoricalFS!I43 -> 1.7488918 | E15: =HistoricalFS!J43 -> 0.22140045 | F15: =HistoricalFS!K43 -> 0.19825846 | G15: =HistoricalFS!L43 -> 0.10864667
B16: Dividend Per Share | C16: =HistoricalFS!H45 -> 3.1499909 | D16: =HistoricalFS!I45 -> 6.1499789 | E16: =HistoricalFS!J45 -> 6.9999794 | F16: =HistoricalFS!K45 -> 7.249982 | G16: =HistoricalFS!L45 -> 7.7499768
B17: Dividend Growth (YoY) | C17: ='Profit & Loss'!G29 -> -0.48190708 | D17: ='Profit & Loss'!H29 -> 0.95237988 | E17: ='Profit & Loss'!I29 -> 0.13821194 | F17: ='Profit & Loss'!J29 -> 0.035714759 | G17: ='Profit & Loss'!K29 -> 0.068964978
B19: =B6 -> Key Financial Matrix | C19: =C6 -> 43921 | D19: =D6 -> 44286 | E19: =E6 -> 44651 | F19: =F6 -> 45016 | G19: =G6 -> 45382 | I19: Volume - 5Y
B21: Price to Earnings | C21: ='Profit & Loss'!G14 -> 7.1819724 | D21: ='Profit & Loss'!H14 -> 7.0598531 | E21: ='Profit & Loss'!I14 -> 7.8499781 | F21: ='Profit & Loss'!J14 -> 10.039244 | G21: ='Profit & Loss'!K14 -> 15.645633 | H21: ='Profit & Loss'!L14 -> 13.931809
B22: EV / EBITDA | C22: ='Profit & Loss'!G36 -> 7.167928 | D22: ='Profit & Loss'!H36 -> 7.981951 | E22: ='Profit & Loss'!I36 -> 7.5112529 | F22: ='Profit & Loss'!J36 -> 7.7631366 | G22: ='Profit & Loss'!K36 -> 9.9046156
B23: EV / Sales | C23: ='Profit & Loss'!G37 -> 2.5860781 | D23: ='Profit & Loss'!H37 -> 2.7717674 | E23: ='Profit & Loss'!I37 -> 2.5413112 | F23: ='Profit & Loss'!J37 -> 2.2005565 | G23: ='Profit & Loss'!K37 -> 3.1142638
B24: Price to Book Value | C24: ='Profit & Loss'!G39 -> 0.70105285 | D24: ='Profit & Loss'!H39 -> 0.82169235 | E24: ='Profit & Loss'!I39 -> 0.96699293 | F24: ='Profit & Loss'!J39 -> 1.1548467 | G24: ='Profit & Loss'!K39 -> 2.0261133
B25: Return on Equity (%) | C25: ='Ratio Analysis'!H28 -> 0.031075783 | D25: ='Ratio Analysis'!I28 -> 0.079121927 | E25: ='Ratio Analysis'!J28 -> 0.089761205 | F25: ='Ratio Analysis'!K28 -> 0.099034798 | G25: ='Ratio Analysis'!L28 -> 0.10044442 | H25: ='Ratio Analysis'!M28 -> 0
B26: Return on Capital Employed (%) | C26: ='Ratio Analysis'!H26 -> 0.065966506 | D26: ='Ratio Analysis'!I26 -> 0.064276366 | E26: ='Ratio Analysis'!J26 -> 0.076785908 | F26: ='Ratio Analysis'!K26 -> 0.088673854 | G26: ='Ratio Analysis'!L26 -> 0.088608581 | H26: ='Ratio Analysis'!M26 -> 0
B28: ="Top Shareholders of" & " - " & 'Data Sheet'!B1 -> Top Shareholders of - NTPC LTD | C28: ='Share Price - 5Y'!I21 -> N. Shares (In Crs.) | E28: % Holding | F28: ='Share Price - 5Y'!K21 -> Market Value (In Crs.) | I28: Shareholding Patterns
B30: ='Share Price - 5Y'!H22 -> President Of India | C30: ='Share Price - 5Y'!I22 -> 495.53463 | E30: ='Share Price - 5Y'!J22 -> 0.511 | F30: ='Share Price - 5Y'!K22 -> 161668.17
B31: ='Share Price - 5Y'!H23 -> Icici Prudential Equity & Debt Fund | C31: ='Share Price - 5Y'!I23 -> 41.249902 | E31: ='Share Price - 5Y'!J23 -> 0.0425 | F31: ='Share Price - 5Y'!K23 -> 13457.78
B32: ='Share Price - 5Y'!H24 -> Life Insurance Corporation Of India | C32: ='Share Price - 5Y'!I24 -> 38.442476 | E32: ='Share Price - 5Y'!J24 -> 0.0396 | F32: ='Share Price - 5Y'!K24 -> 12541.858
B33: ='Share Price - 5Y'!H25 -> Cpse Exchange Traded Scheme (cpse Etf) | C33: ='Share Price - 5Y'!I25 -> 36.730436 | E33: ='Share Price - 5Y'!J25 -> 0.0379 | F33: ='Share Price - 5Y'!K25 -> 11983.305
B34: ='Share Price - 5Y'!H26 -> Government Of Singapore | C34: ='Share Price - 5Y'!I26 -> 22.337466 | E34: ='Share Price - 5Y'!J26 -> 0.023 | F34: ='Share Price - 5Y'!K26 -> 7287.5982
B35: ='Share Price - 5Y'!H27 -> Sbi Nifty 50 Etf | C35: ='Share Price - 5Y'!I27 -> 18.66853 | E35: ='Share Price - 5Y'!J27 -> 0.0193 | F35: ='Share Price - 5Y'!K27 -> 6090.6078
B36: ='Share Price - 5Y'!H28 -> Hdfc Trustee Company Ltd. A/c Hdfc Balanced A | C36: ='Share Price - 5Y'!I28 -> 18.483343 | E36: ='Share Price - 5Y'!J28 -> 0.0191 | F36: ='Share Price - 5Y'!K28 -> 6030.1907
B37: ='Share Price - 5Y'!H29 -> Nps Trust- A/c Hdfc Pension Fund Management L | C37: ='Share Price - 5Y'!I29 -> 15.834972 | E37: ='Share Price - 5Y'!J29 -> 0.0163 | F37: ='Share Price - 5Y'!K29 -> 5166.1595
B38: ='Share Price - 5Y'!H30 -> Investor Education and Protection Fund (IEPF) | C38: ='Share Price - 5Y'!I30 -> 0.1788723 | E38: ='Share Price - 5Y'!J30 -> 0.0002 | F38: ='Share Price - 5Y'!K30 -> 58.357088
B40: Managerial Remuneration | C40: Designation | D40: Remuneration | F40: X of Median Salary | I40: Capital Structure
B42: Shri Gurdeep Singh | C42: CMD | D42: 1.59 | G42: N/A | I42: Share Price as on | K42: ='Data Sheet'!B8 -> 315.8
B43: Shri Dillip Kumar Patel | C43: Dir (HR) | D43: 1.09 | G43: N/A | I43: Number of Shares O/S | K43: ='Data Sheet'!B6 -> 969.66672
B44: Shri Ramesh Babu V | C44: Dir (Ops) | D44: 1.72 | G44: N/A | I44: Market Capitalization | K44: =K42*K43 -> 306220.75
B45: Shri Ujjwal Kanti Bhattacharya | C45: Dir (Proj) | D45: 1.51 | G45: N/A | I45: Less: Cash & Equivalents | K45: ='Data Sheet'!K70*-1 -> -6847.34
I46: Add: Total Debt | K46: ='Data Sheet'!K60 -> 237130.98
B47: Note: | I47: Add: Minority Interset | K47: 4413.01
B48: The median salary ratio isn’t provided due to government company exemptions. Instead, the table shows each director’s share of total employee payroll for transparency. | I48: Enterprise Value | K48: =SUM(K44:K47) -> 540917.4
B50: Recent Updates
...

Sheet HistoricalFS
B3: =B7 -> Historical Financial Statement - NTPC LTD
B7: ="Historical Financial Statement - " & 'Data Sheet'!B1 -> Historical Financial Statement - NTPC LTD
B8: Years | C8: ='Data Sheet'!B57 -> 42094 | D8: ='Data Sheet'!C57 -> 42460 | E8: ='Data Sheet'!D57 -> 42825 | F8: ='Data Sheet'!E57 -> 43190 | G8: ='Data Sheet'!F57 -> 43555 | H8: ='Data Sheet'!G57 -> 43921 | I8: ='Data Sheet'!H57 -> 44286 | J8: ='Data Sheet'!I57 -> 44651 | ... L8: ='Data Sheet'!K57 -> 45382 | M8: LTM
A9: # | B9: Income Statement
B10: Sales | C10: =IFERROR('Data Sheet'!B17,0) -> 79956.74 | D10: =IFERROR('Data Sheet'!C17,0) -> 73396.32 | E10: =IFERROR('Data Sheet'!D17,0) -> 82042.49 | F10: =IFERROR('Data Sheet'!E17,0) -> 88083.31 | G10: =IFERROR('Data Sheet'!F17,0) -> 100286.54 | H10: =IFERROR('Data Sheet'!G17,0) -> 109464.04 | I10: =IFERROR('Data Sheet'!H17,0) -> 111531.15 | J10: =IFERROR('Data Sheet'!I17,0) -> 132669.28 | ... L10: =IFERROR('Data Sheet'!K17,0) -> 178500.88 | M10: =IFERROR(SUM('Data Sheet'!H43:K43),0) -> 185891.75
B11: Sales Growth % | C11: - | D11: =D10/C10-1 -> -0.082049618 | E11: =E10/D10-1 -> 0.11780114 | F11: =F10/E10-1 -> 0.073630383 | G11: =G10/F10-1 -> 0.13854191 | H11: =H10/G10-1 -> 0.091512779 | I11: =I10/H10-1 -> 0.018883918 | J11: =J10/I10-1 -> 0.18952669 | K11: =K10/J10-1 -> 0.32816866 | ... M11: =M10/L10-1 -> 0.04140523
B13: Cost of Goods Sold | C13: =IFERROR(SUM('Data Sheet'!B18,'Data Sheet'!B20:B22)-1*'Data Sheet'!B19,0) -> 62480.32 | D13: =IFERROR(SUM('Data Sheet'!C18,'Data Sheet'!C20:C22)-1*'Data Sheet'!C19,0) -> 54652.18 | E13: =IFERROR(SUM('Data Sheet'!D18,'Data Sheet'!D20:D22)-1*'Data Sheet'!D19,0) -> 60357.15 | F13: =IFERROR(SUM('Data Sheet'!E18,'Data Sheet'!E20:E22)-1*'Data Sheet'!E19,0) -> 64386.18 | G13: =IFERROR(SUM('Data Sheet'!F18,'Data Sheet'!F20:F22)-1*'Data Sheet'!F19,0) -> 72237.19 | H13: =IFERROR(SUM('Data Sheet'!G18,'Data Sheet'!G20:G22)-1*'Data Sheet'!G19,0) -> 75620.02 | I13: =IFERROR(SUM('Data Sheet'!H18,'Data Sheet'!H20:H22)-1*'Data Sheet'!H19,0) -> 75111.64 | J13: =IFERROR(SUM('Data Sheet'!I18,'Data Sheet'!I20:I22)-1*'Data Sheet'!I19,0) -> 91225.79 | ... M13: =IFERROR(SUM('Data Sheet'!L18,'Data Sheet'!L20:L22)-1*'Data Sheet'!L19,0) -> 0
B14: COGS % Sales | C14: =C13/C10 -> 0.78142656 | D14: =D13/D10 -> 0.74461744 | E14: =E13/E10 -> 0.7356816 | F14: =F13/F10 -> 0.73096912 | G14: =G13/G10 -> 0.72030793 | H14: =H13/H10 -> 0.69082066 | I14: =I13/I10 -> 0.67345885 | J14: =J13/J10 -> 0.68761804 | ... M14: =M13/M10 -> 0
B16: Gross Profit | C16: =C10-C13 -> 17476.42 | D16: =D10-D13 -> 18744.14 | E16: =E10-E13 -> 21685.34 | F16: =F10-F13 -> 23697.13 | G16: =G10-G13 -> 28049.35 | H16: =H10-H13 -> 33844.02 | I16: =I10-I13 -> 36419.51 | J16: =J10-J13 -> 41443.49 | ... M16: =M10-M13 -> 185891.75
B17: Gross Margin | C17: =C16/C10 -> 0.21857344 | D17: =D16/D10 -> 0.25538256 | E17: =E16/E10 -> 0.2643184 | F17: =F16/F10 -> 0.26903088 | G17: =G16/G10 -> 0.27969207 | H17: =H16/H10 -> 0.30917934 | I17: =I16/I10 -> 0.32654115 | J17: =J16/J10 -> 0.31238196 | ... M17: =M16/M10 -> 1
B19: Selling & Genenral Expenses | C19: =IFERROR(SUM('Data Sheet'!B23:B24),0) -> 124.3 | D19: =IFERROR(SUM('Data Sheet'!C23:C24),0) -> 176.64 | E19: =IFERROR(SUM('Data Sheet'!D23:D24),0) -> 87.81 | F19: =IFERROR(SUM('Data Sheet'!E23:E24),0) -> 1211.72 | G19: =IFERROR(SUM('Data Sheet'!F23:F24),0) -> 5338.98 | H19: =IFERROR(SUM('Data Sheet'!G23:G24),0) -> 2258.29 | I19: =IFERROR(SUM('Data Sheet'!H23:H24),0) -> 2375.79 | J19: =IFERROR(SUM('Data Sheet'!I23:I24),0) -> 1081.57 | ... L19: =IFERROR(SUM('Data Sheet'!K23:K24),0) -> 888.11
B20: S&G Exp % Sales | C20: =C19/C10 -> 0.0015545906 | D20: =D19/D10 -> 0.0024066602 | E20: =E19/E10 -> 0.0010702991 | F20: =F19/F10 -> 0.013756522 | G20: =G19/G10 -> 0.053237254 | H20: =H19/H10 -> 0.020630428 | I20: =I19/I10 -> 0.021301583 | J20: =J19/J10 -> 0.0081523771 | ... M20: =M19/M10 -> 0
B22: EBITDA | C22: =C16-C19 -> 17352.12 | D22: =D16-D19 -> 18567.5 | E22: =E16-E19 -> 21597.53 | F22: =F16-F19 -> 22485.41 | G22: =G16-G19 -> 22710.37 | H22: =H16-H19 -> 31585.73 | I22: =I16-I19 -> 34043.72 | J22: =J16-J19 -> 40361.92 | ... L22: =L16-L19 -> 51455.69 | M22: =IFERROR(SUM('Data Sheet'!H28:K28),0) -> 91456.44
B23: EBITDA % Sales | C23: =C22/C10 -> 0.21701885 | D23: =D22/D10 -> 0.2529759 | E23: =E22/E10 -> 0.2632481 | F23: =F22/F10 -> 0.25527435 | G23: =G22/G10 -> 0.22645482 | H23: =H22/H10 -> 0.28854892 | I23: =I22/I10 -> 0.30523957 | J23: =J22/J10 -> 0.30422959 | ... M23: =M22/M10 -> 0.49198762
B25: Interest | C25: =IFERROR('Data Sheet'!B27,0) -> 3668.98 | D25: =IFERROR('Data Sheet'!C27,0) -> 3366.03 | E25: =IFERROR('Data Sheet'!D27,0) -> 3752.8 | F25: =IFERROR('Data Sheet'!E27,0) -> 4446.59 | G25: =IFERROR('Data Sheet'!F27,0) -> 5604.65 | H25: =IFERROR('Data Sheet'!G27,0) -> 8189.01 | I25: =IFERROR('Data Sheet'!H27,0) -> 9224.21 | J25: =IFERROR('Data Sheet'!I27,0) -> 9375.68 | ... L25: =IFERROR('Data Sheet'!K27,0) -> 12300.51 | M25: =IFERROR(SUM('Data Sheet'!H47:L47),0) -> 12475.28
B26: Interest % Sales | C26: =C25/C10 -> 0.045887063 | D26: =D25/D10 -> 0.045861019 | E26: =E25/E10 -> 0.045742151 | F26: =F25/F10 -> 0.050481641 | G26: =G25/G10 -> 0.055886363 | H26: =H25/H10 -> 0.074810047 | I26: =I25/I10 -> 0.082705235 | J26: =J25/J10 -> 0.070669563 | ... M26: =M25/M10 -> 0.067110455
B28: Depericiation | C28: =IFERROR('Data Sheet'!B26,0) -> 5564.61 | D28: =IFERROR('Data Sheet'!C26,0) -> 5771.24 | E28: =IFERROR('Data Sheet'!D26,0) -> 6009.91 | F28: =IFERROR('Data Sheet'!E26,0) -> 7459.93 | G28: =IFERROR('Data Sheet'!F26,0) -> 8669.03 | H28: =IFERROR('Data Sheet'!G26,0) -> 10356.16 | I28: =IFERROR('Data Sheet'!H26,0) -> 12450.31 | J28: =IFERROR('Data Sheet'!I26,0) -> 13787.83 | ... L28: =IFERROR('Data Sheet'!K26,0) -> 16203.63 | M28: =IFERROR(SUM('Data Sheet'!H46:K46),0) -> 17008.88
B29: Depericiation % Sales | C29: =C28/C10 -> 0.069595259 | D29: =D28/D10 -> 0.07863119 | E29: =E28/E10 -> 0.073253627 | F29: =F28/F10 -> 0.084691754 | G29: =G28/G10 -> 0.086442607 | H29: =H28/H10 -> 0.094607873 | I29: =I28/I10 -> 0.11163079 | J29: =J28/J10 -> 0.10392632 | ... M29: =M28/M10 -> 0.091498843
B31: Earnings Before Tax | C31: =IFERROR(C22-SUM(C28,C25),0) -> 8118.53 | D31: =IFERROR(D22-SUM(D28,D25),0) -> 9430.23 | E31: =IFERROR(E22-SUM(E28,E25),0) -> 11834.82 | F31: =IFERROR(F22-SUM(F28,F25),0) -> 10578.89 | G31: =IFERROR(G22-SUM(G28,G25),0) -> 8436.69 | H31: =IFERROR(H22-SUM(H28,H25),0) -> 13040.56 | I31: =IFERROR(I22-SUM(I28,I25),0) -> 12369.2 | J31: =IFERROR(J22-SUM(J28,J25),0) -> 17198.41 | ... M31: =IFERROR(M22-SUM(M28,M25),0) -> 61972.28
B32: EBT % Sales | C32: =C31/C10 -> 0.10153653 | D32: =D31/D10 -> 0.12848369 | E32: =E31/E10 -> 0.14425233 | F32: =F31/F10 -> 0.12010096 | G32: =G31/G10 -> 0.084125846 | H32: =H31/H10 -> 0.11913099 | I32: =I31/I10 -> 0.11090355 | J32: =J31/J10 -> 0.1296337 | ... M32: =M31/M10 -> 0.33337832
B34: Tax | C34: =IFERROR('Data Sheet'!B29,) -> 463.84 | D34: =IFERROR('Data Sheet'!C29,) -> -162.81 | E34: =IFERROR('Data Sheet'!D29,) -> 2712.39 | F34: =IFERROR('Data Sheet'!E29,) -> 5652.94 | G34: =IFERROR('Data Sheet'!F29,) -> -2779.94 | H34: =IFERROR('Data Sheet'!G29,) -> 9347.54 | I34: =IFERROR('Data Sheet'!H29,) -> 2420.53 | J34: =IFERROR('Data Sheet'!I29,) -> 5047.1 | ... L34: =IFERROR('Data Sheet'!K29,) -> 6809.2 | M34: =IFERROR(SUM('Data Sheet'!H49:K49),) -> 7193.2
B35: Effective Tax Rate | C35: =C34/C31 -> 0.057133496 | D35: =D34/D31 -> -0.01726469 | E35: =E34/E31 -> 0.22918726 | F35: =F34/F31 -> 0.53436041 | G35: =G34/G31 -> -0.329506 | H35: =H34/H31 -> 0.71680511 | I35: =I34/I31 -> 0.1956901 | J35: =J34/J31 -> 0.29346317 | ... M35: =M34/M31 -> 0.11607125
B37: Net Profit | C37: =C31-C34 -> 7654.69 | D37: =D31-D34 -> 9593.04 | E37: =E31-E34 -> 9122.43 | F37: =F31-F34 -> 4925.95 | G37: =G31-G34 -> 11216.63 | H37: =H31-H34 -> 3693.02 | I37: =I31-I34 -> 9948.67 | J37: =J31-J34 -> 12151.31 | ... M37: =M31-M34 -> 54779.08
B38: Net Margins | C38: =C37/C10 -> 0.095735394 | D38: =D37/D10 -> 0.13070192 | E38: =E37/E10 -> 0.11119153 | F38: =F37/F10 -> 0.055923761 | G38: =G37/G10 -> 0.11184582 | H38: =H37/H10 -> 0.033737289 | I38: =I37/I10 -> 0.08920082 | J38: =J37/J10 -> 0.091590985 | ... M38: =M37/M10 -> 0.29468268
B40: No of Equity Shares | C40: =IFERROR('Data Sheet'!B94,) -> 989.46 | D40: =IFERROR('Data Sheet'!C94,) -> 989.46 | E40: =IFERROR('Data Sheet'!D94,) -> 989.46 | F40: =IFERROR('Data Sheet'!E94,) -> 989.46 | G40: =IFERROR('Data Sheet'!F94,) -> 989.46 | H40: =IFERROR('Data Sheet'!G94,) -> 989.46 | I40: =IFERROR('Data Sheet'!H94,) -> 969.67 | J40: =IFERROR('Data Sheet'!I94,) -> 969.67 | ... L40: =IFERROR('Data Sheet'!K94,) -> 969.67 | M40: =L40 -> 969.67
B42: EPS | C42: =IFERROR(C37/C40,0) -> 7.7362299 | D42: =IFERROR(D37/D40,0) -> 9.6952277 | E42: =IFERROR(E37/E40,0) -> 9.2196046 | F42: =IFERROR(F37/F40,0) -> 4.9784226 | G42: =IFERROR(G37/G40,0) -> 11.336113 | H42: =IFERROR(H37/H40,0) -> 3.7323591 | I42: =IFERROR(I37/I40,0) -> 10.259851 | J42: =IFERROR(J37/J40,0) -> 12.531387 | ... M42: =IFERROR(M37/M40,0) -> 56.492497
B43: EPS Growth % | C43: - | D43: =IFERROR(D42/C42-1,0) -> 0.25322384 | E43: =IFERROR(E42/D42-1,0) -> -0.049057442 | F43: =IFERROR(F42/E42-1,0) -> -0.46001778 | G43: =IFERROR(G42/F42-1,0) -> 1.2770491 | H43: =IFERROR(H42/G42-1,0) -> -0.67075494 | I43: =IFERROR(I42/H42-1,0) -> 1.7488918 | J43: =IFERROR(J42/I42-1,0) -> 0.22140045 | K43: =IFERROR(K42/J42-1,0) -> 0.19825846 | ... M43: =IFERROR(M42/L42-1,0) -> 2.3935009
B45: Dividend per share | C45: =IFERROR('Data Sheet'!B31/HistoricalFS!C40,0) -> 2.0833182 | D45: =IFERROR('Data Sheet'!C31/HistoricalFS!D40,0) -> 2.791654 | E45: =IFERROR('Data Sheet'!D31/HistoricalFS!E40,0) -> 3.9833141 | F45: =IFERROR('Data Sheet'!E31/HistoricalFS!F40,0) -> 4.2666505 | G45: =IFERROR('Data Sheet'!F31/HistoricalFS!G40,0) -> 6.0799729 | H45: =IFERROR('Data Sheet'!G31/HistoricalFS!H40,0) -> 3.1499909 | I45: =IFERROR('Data Sheet'!H31/HistoricalFS!I40,0) -> 6.1499789 | J45: =IFERROR('Data Sheet'!I31/HistoricalFS!J40,0) -> 6.9999794 | ... M45: =IFERROR('Data Sheet'!L31/HistoricalFS!M40,0) -> 0
B46: Dividend payout ratio | C46: =IFERROR(C45/C42,0) -> 0.26929373 | D46: =IFERROR(D45/D42,0) -> 0.28794105 | E46: =IFERROR(E45/E42,0) -> 0.43204826 | F46: =IFERROR(F45/F42,0) -> 0.85702859 | G46: =IFERROR(G45/G42,0) -> 0.53633667 | H46: =IFERROR(H45/H42,0) -> 0.84396781 | I46: =IFERROR(I45/I42,0) -> 0.59942183 | J46: =IFERROR(J45/J42,0) -> 0.55859574 | ... M46: =IFERROR(M45/M42,0) -> 0
B48: Retained Earnings | C48: =IFERROR(IF(C42>C45,1-C46,0),0) -> 0.73070627 | D48: =IFERROR(IF(D42>D45,1-D46,0),0) -> 0.71205895 | E48: =IFERROR(IF(E42>E45,1-E46,0),0) -> 0.56795174 | F48: =IFERROR(IF(F42>F45,1-F46,0),0) -> 0.14297141 | G48: =IFERROR(IF(G42>G45,1-G46,0),0) -> 0.46366333 | H48: =IFERROR(IF(H42>H45,1-H46,0),0) -> 0.15603219 | I48: =IFERROR(IF(I42>I45,1-I46,0),0) -> 0.40057817 | J48: =IFERROR(IF(J42>J45,1-J46,0),0) -> 0.44140426 | ... M48: =IFERROR(IF(M42>M45,1-M46,0),0) -> 1
A53: # | B53: Balance Sheet
B54: Equity Share Capital | C54: =IFERROR('Data Sheet'!B58,0) -> 8245.46 | D54: =IFERROR('Data Sheet'!C58,0) -> 8245.46 | E54: =IFERROR('Data Sheet'!D58,0) -> 8245.46 | F54: =IFERROR('Data Sheet'!E58,0) -> 8245.46 | G54: =IFERROR('Data Sheet'!F58,0) -> 9894.56 | H54: =IFERROR('Data Sheet'!G58,0) -> 9894.56 | I54: =IFERROR('Data Sheet'!H58,0) -> 9696.67 | J54: =IFERROR('Data Sheet'!I58,0) -> 9696.67 | ... L54: =IFERROR('Data Sheet'!K58,0) -> 9696.67
B55: Reserves | C55: =IFERROR('Data Sheet'!B59,0) -> 73848.52 | D55: =IFERROR('Data Sheet'!C59,0) -> 83330.12 | E55: =IFERROR('Data Sheet'!D59,0) -> 89592.56 | F55: =IFERROR('Data Sheet'!E59,0) -> 95318.01 | G55: =IFERROR('Data Sheet'!F59,0) -> 101461.65 | H55: =IFERROR('Data Sheet'!G59,0) -> 108944.6 | I55: =IFERROR('Data Sheet'!H59,0) -> 116041.8 | J55: =IFERROR('Data Sheet'!I59,0) -> 125677.07 | ... L55: =IFERROR('Data Sheet'!K59,0) -> 151012.6
B56: Borrowings | C56: =IFERROR('Data Sheet'!B60,0) -> 102252 | D56: =IFERROR('Data Sheet'!C60,0) -> 99423.55 | E56: =IFERROR('Data Sheet'!D60,0) -> 113773.2 | F56: =IFERROR('Data Sheet'!E60,0) -> 130048.56 | G56: =IFERROR('Data Sheet'!F60,0) -> 173058.23 | H56: =IFERROR('Data Sheet'!G60,0) -> 202984.31 | I56: =IFERROR('Data Sheet'!H60,0) -> 210207.87 | J56: =IFERROR('Data Sheet'!I60,0) -> 210706.56 | ... L56: =IFERROR('Data Sheet'!K60,0) -> 237130.98
B57: Other Liabilities | C57: =IFERROR('Data Sheet'!B61,0) -> 35366.06 | D57: =IFERROR('Data Sheet'!C61,0) -> 33665.93 | E57: =IFERROR('Data Sheet'!D61,0) -> 36989.6 | F57: =IFERROR('Data Sheet'!E61,0) -> 48880.23 | G57: =IFERROR('Data Sheet'!F61,0) -> 62508.55 | H57: =IFERROR('Data Sheet'!G61,0) -> 55745.53 | I57: =IFERROR('Data Sheet'!H61,0) -> 62075.45 | J57: =IFERROR('Data Sheet'!I61,0) -> 69751.12 | ... L57: =IFERROR('Data Sheet'!K61,0) -> 81437.47
B58: Total Liability | C58: =IFERROR('Data Sheet'!B62,0) -> 219712.04 | D58: =IFERROR('Data Sheet'!C62,0) -> 224665.06 | E58: =IFERROR('Data Sheet'!D62,0) -> 248600.82 | F58: =IFERROR('Data Sheet'!E62,0) -> 282492.26 | G58: =IFERROR('Data Sheet'!F62,0) -> 346922.99 | H58: =IFERROR('Data Sheet'!G62,0) -> 377569 | I58: =IFERROR('Data Sheet'!H62,0) -> 398021.79 | J58: =IFERROR('Data Sheet'!I62,0) -> 415831.42 | ... L58: =IFERROR('Data Sheet'!K62,0) -> 479277.72
B60: Fixed Assets Net Block | C60: =IFERROR('Data Sheet'!B63,0) -> 91853.02 | D60: =IFERROR('Data Sheet'!C63,0) -> 92929.36 | E60: =IFERROR('Data Sheet'!D63,0) -> 104531.66 | F60: =IFERROR('Data Sheet'!E63,0) -> 128245.42 | G60: =IFERROR('Data Sheet'!F63,0) -> 150984.53 | H60: =IFERROR('Data Sheet'!G63,0) -> 187802.79 | I60: =IFERROR('Data Sheet'!H63,0) -> 203245.18 | J60: =IFERROR('Data Sheet'!I63,0) -> 224923.02 | ... L60: =IFERROR('Data Sheet'!K63,0) -> 258933.63
B61: Capital Work in Progress | C61: =IFERROR('Data Sheet'!B64,0) -> 67554.69 | D61: =IFERROR('Data Sheet'!C64,0) -> 75045.53 | E61: =IFERROR('Data Sheet'!D64,0) -> 86895.71 | F61: =IFERROR('Data Sheet'!E64,0) -> 83386.1 | G61: =IFERROR('Data Sheet'!F64,0) -> 118396.86 | H61: =IFERROR('Data Sheet'!G64,0) -> 98508.47 | I61: =IFERROR('Data Sheet'!H64,0) -> 97506.03 | J61: =IFERROR('Data Sheet'!I64,0) -> 91126.26 | ... L61: =IFERROR('Data Sheet'!K64,0) -> 87664.45
B62: Investments | C62: =IFERROR('Data Sheet'!B65,0) -> 1901.51 | D62: =IFERROR('Data Sheet'!C65,0) -> 6473.36 | E62: =IFERROR('Data Sheet'!D65,0) -> 7613.92 | F62: =IFERROR('Data Sheet'!E65,0) -> 8875.61 | G62: =IFERROR('Data Sheet'!F65,0) -> 8132.31 | H62: =IFERROR('Data Sheet'!G65,0) -> 9306.59 | I62: =IFERROR('Data Sheet'!H65,0) -> 10589.25 | J62: =IFERROR('Data Sheet'!I65,0) -> 10626.24 | ... L62: =IFERROR('Data Sheet'!K65,0) -> 15884.56
B63: Other Assets | C63: =IFERROR('Data Sheet'!B66-SUM('Data Sheet'!B68:B70),0) -> 26841.59 | D63: =IFERROR('Data Sheet'!C66-SUM('Data Sheet'!C68:C70),0) -> 29845.15 | E63: =IFERROR('Data Sheet'!D66-SUM('Data Sheet'!D68:D70),0) -> 30604.59 | F63: =IFERROR('Data Sheet'!E66-SUM('Data Sheet'!E68:E70),0) -> 42514.46 | G63: =IFERROR('Data Sheet'!F66-SUM('Data Sheet'!F68:F70),0) -> 45598.89 | H63: =IFERROR('Data Sheet'!G66-SUM('Data Sheet'!G68:G70),0) -> 47103.57 | I63: =IFERROR('Data Sheet'!H66-SUM('Data Sheet'!H68:H70),0) -> 44074.06 | J63: =IFERROR('Data Sheet'!I66-SUM('Data Sheet'!I68:I70),0) -> 46356.95 | ... L63: =IFERROR('Data Sheet'!K66-SUM('Data Sheet'!K68:K70),0) -> 58327.89
...

Sheet Common Size Statement
B3: =B7 -> Common Size Income Statement -NTPC LTD
B7: ="Common Size Income Statement" & " "& "-" & 'Data Sheet'!$B$1 -> Common Size Income Statement -NTPC LTD
B9: Particulars | C9: ='Data Sheet'!B16 -> 42094 | D9: ='Data Sheet'!C16 -> 42460 | E9: ='Data Sheet'!D16 -> 42825 | F9: ='Data Sheet'!E16 -> 43190 | G9: ='Data Sheet'!F16 -> 43555 | H9: ='Data Sheet'!G16 -> 43921 | I9: ='Data Sheet'!H16 -> 44286 | J9: ='Data Sheet'!I16 -> 44651 | ... L9: ='Data Sheet'!K16 -> 45382
B11: ='Data Sheet'!A17 -> Sales | C11: ='Data Sheet'!B17/'Data Sheet'!B$17 -> 1 | D11: ='Data Sheet'!C17/'Data Sheet'!C$17 -> 1 | E11: ='Data Sheet'!D17/'Data Sheet'!D$17 -> 1 | F11: ='Data Sheet'!E17/'Data Sheet'!E$17 -> 1 | G11: ='Data Sheet'!F17/'Data Sheet'!F$17 -> 1 | H11: ='Data Sheet'!G17/'Data Sheet'!G$17 -> 1 | I11: ='Data Sheet'!H17/'Data Sheet'!H$17 -> 1 | J11: ='Data Sheet'!I17/'Data Sheet'!I$17 -> 1 | ... L11: ='Data Sheet'!K17/'Data Sheet'!K$17 -> 1
B12: ='Data Sheet'!A18 -> Raw Material Cost | C12: ='Data Sheet'!B18/'Data Sheet'!B$17 -> 0 | D12: ='Data Sheet'!C18/'Data Sheet'!C$17 -> 0 | E12: ='Data Sheet'!D18/'Data Sheet'!D$17 -> 0 | F12: ='Data Sheet'!E18/'Data Sheet'!E$17 -> 0 | G12: ='Data Sheet'!F18/'Data Sheet'!F$17 -> 0 | H12: ='Data Sheet'!G18/'Data Sheet'!G$17 -> 0 | I12: ='Data Sheet'!H18/'Data Sheet'!H$17 -> 0 | J12: ='Data Sheet'!I18/'Data Sheet'!I$17 -> 0 | ... L12: ='Data Sheet'!K18/'Data Sheet'!K$17 -> 0
B13: ='Data Sheet'!A19 -> Change in Inventory | C13: ='Data Sheet'!B19/'Data Sheet'!B$17 -> -5.803138e-05 | D13: ='Data Sheet'!C19/'Data Sheet'!C$17 -> 0 | E13: ='Data Sheet'!D19/'Data Sheet'!D$17 -> 0 | F13: ='Data Sheet'!E19/'Data Sheet'!E$17 -> 0 | G13: ='Data Sheet'!F19/'Data Sheet'!F$17 -> 0 | H13: ='Data Sheet'!G19/'Data Sheet'!G$17 -> 0 | I13: ='Data Sheet'!H19/'Data Sheet'!H$17 -> 0 | J13: ='Data Sheet'!I19/'Data Sheet'!I$17 -> 0 | ... L13: ='Data Sheet'!K19/'Data Sheet'!K$17 -> 0
B14: ='Data Sheet'!A20 -> Power and Fuel | C14: ='Data Sheet'!B20/'Data Sheet'!B$17 -> 0.67871952 | D14: ='Data Sheet'!C20/'Data Sheet'!C$17 -> 0.65026816 | E14: ='Data Sheet'!D20/'Data Sheet'!D$17 -> 0.64052724 | F14: ='Data Sheet'!E20/'Data Sheet'!E$17 -> 0.63224883 | G14: ='Data Sheet'!F20/'Data Sheet'!F$17 -> 0.62672967 | H14: ='Data Sheet'!G20/'Data Sheet'!G$17 -> 0.60204931 | I14: ='Data Sheet'!H20/'Data Sheet'!H$17 -> 0.58118974 | J14: ='Data Sheet'!I20/'Data Sheet'!I$17 -> 0.59829389 | ... L14: ='Data Sheet'!K20/'Data Sheet'!K$17 -> 0.62679198
B15: ='Data Sheet'!A21 -> Other Mfr. Exp | C15: ='Data Sheet'!B21/'Data Sheet'!B$17 -> 0.04158186 | D15: ='Data Sheet'!C21/'Data Sheet'!C$17 -> 0.030389807 | E15: ='Data Sheet'!D21/'Data Sheet'!D$17 -> 0.031246736 | F15: ='Data Sheet'!E21/'Data Sheet'!E$17 -> 0.033341844 | G15: ='Data Sheet'!F21/'Data Sheet'!F$17 -> 0.03460245 | H15: ='Data Sheet'!G21/'Data Sheet'!G$17 -> 0.0348963 | I15: ='Data Sheet'!H21/'Data Sheet'!H$17 -> 0.038337899 | J15: ='Data Sheet'!I21/'Data Sheet'!I$17 -> 0.0351027 | ... L15: ='Data Sheet'!K21/'Data Sheet'!K$17 -> 0.037754884
B16: ='Data Sheet'!A22 -> Employee Cost | C16: ='Data Sheet'!B22/'Data Sheet'!B$17 -> 0.061067147 | D16: ='Data Sheet'!C22/'Data Sheet'!C$17 -> 0.063959474 | E16: ='Data Sheet'!D22/'Data Sheet'!D$17 -> 0.063907617 | F16: ='Data Sheet'!E22/'Data Sheet'!E$17 -> 0.065378447 | G16: ='Data Sheet'!F22/'Data Sheet'!F$17 -> 0.058975811 | H16: ='Data Sheet'!G22/'Data Sheet'!G$17 -> 0.053875044 | I16: ='Data Sheet'!H22/'Data Sheet'!H$17 -> 0.053931211 | J16: ='Data Sheet'!I22/'Data Sheet'!I$17 -> 0.054221444 | ... L16: ='Data Sheet'!K22/'Data Sheet'!K$17 -> 0.042212005
B17: ='Data Sheet'!A23 -> Selling and admin | C17: ='Data Sheet'!B23/'Data Sheet'!B$17 -> 0.025848728 | D17: ='Data Sheet'!C23/'Data Sheet'!C$17 -> 0.022483144 | E17: ='Data Sheet'!D23/'Data Sheet'!D$17 -> 0.019891522 | F17: ='Data Sheet'!E23/'Data Sheet'!E$17 -> 0.02026729 | G17: ='Data Sheet'!F23/'Data Sheet'!F$17 -> 0.026082364 | H17: ='Data Sheet'!G23/'Data Sheet'!G$17 -> 0.030319455 | I17: ='Data Sheet'!H23/'Data Sheet'!H$17 -> 0.033858433 | J17: ='Data Sheet'!I23/'Data Sheet'!I$17 -> 0.034799465 | ... L17: ='Data Sheet'!K23/'Data Sheet'!K$17 -> 0.042781918
B18: ='Data Sheet'!A24 -> Other Expenses | C18: ='Data Sheet'!B24/'Data Sheet'!B$17 -> -0.024294137 | D18: ='Data Sheet'!C24/'Data Sheet'!C$17 -> -0.020076483 | E18: ='Data Sheet'!D24/'Data Sheet'!D$17 -> -0.018821223 | F18: ='Data Sheet'!E24/'Data Sheet'!E$17 -> -0.006510768 | G18: ='Data Sheet'!F24/'Data Sheet'!F$17 -> 0.02715489 | H18: ='Data Sheet'!G24/'Data Sheet'!G$17 -> -0.0096890266 | I18: ='Data Sheet'!H24/'Data Sheet'!H$17 -> -0.012556851 | J18: ='Data Sheet'!I24/'Data Sheet'!I$17 -> -0.026647088 | ... L18: ='Data Sheet'!K24/'Data Sheet'!K$17 -> -0.037806536
B19: ='Data Sheet'!A25 -> Other Income | C19: ='Data Sheet'!B25/'Data Sheet'!B$17 -> 0.02923681 | D19: ='Data Sheet'!C25/'Data Sheet'!C$17 -> 0.016181874 | E19: ='Data Sheet'!D25/'Data Sheet'!D$17 -> 0.019398607 | F19: ='Data Sheet'!E25/'Data Sheet'!E$17 -> 0.063298598 | G19: ='Data Sheet'!F25/'Data Sheet'!F$17 -> 0.028098088 | H19: ='Data Sheet'!G25/'Data Sheet'!G$17 -> 0.074992299 | I19: ='Data Sheet'!H25/'Data Sheet'!H$17 -> 0.045016392 | J19: ='Data Sheet'!I25/'Data Sheet'!I$17 -> 0.036247879 | ... L19: ='Data Sheet'!K25/'Data Sheet'!K$17 -> 0.029076047
B20: ='Data Sheet'!A26 -> Depreciation | C20: ='Data Sheet'!B26/'Data Sheet'!B$17 -> 0.069595259 | D20: ='Data Sheet'!C26/'Data Sheet'!C$17 -> 0.07863119 | E20: ='Data Sheet'!D26/'Data Sheet'!D$17 -> 0.073253627 | F20: ='Data Sheet'!E26/'Data Sheet'!E$17 -> 0.084691754 | G20: ='Data Sheet'!F26/'Data Sheet'!F$17 -> 0.086442607 | H20: ='Data Sheet'!G26/'Data Sheet'!G$17 -> 0.094607873 | I20: ='Data Sheet'!H26/'Data Sheet'!H$17 -> 0.11163079 | J20: ='Data Sheet'!I26/'Data Sheet'!I$17 -> 0.10392632 | ... L20: ='Data Sheet'!K26/'Data Sheet'!K$17 -> 0.090776191
B21: ='Data Sheet'!A27 -> Interest | C21: ='Data Sheet'!B27/'Data Sheet'!B$17 -> 0.045887063 | D21: ='Data Sheet'!C27/'Data Sheet'!C$17 -> 0.045861019 | E21: ='Data Sheet'!D27/'Data Sheet'!D$17 -> 0.045742151 | F21: ='Data Sheet'!E27/'Data Sheet'!E$17 -> 0.050481641 | G21: ='Data Sheet'!F27/'Data Sheet'!F$17 -> 0.055886363 | H21: ='Data Sheet'!G27/'Data Sheet'!G$17 -> 0.074810047 | I21: ='Data Sheet'!H27/'Data Sheet'!H$17 -> 0.082705235 | J21: ='Data Sheet'!I27/'Data Sheet'!I$17 -> 0.070669563 | ... L21: ='Data Sheet'!K27/'Data Sheet'!K$17 -> 0.06891008
B22: ='Data Sheet'!A28 -> Profit before tax | C22: ='Data Sheet'!B28/'Data Sheet'!B$17 -> 0.13077334 | D22: ='Data Sheet'!C28/'Data Sheet'!C$17 -> 0.14466556 | E22: ='Data Sheet'!D28/'Data Sheet'!D$17 -> 0.16365093 | F22: ='Data Sheet'!E28/'Data Sheet'!E$17 -> 0.18339956 | G22: ='Data Sheet'!F28/'Data Sheet'!F$17 -> 0.11222393 | H22: ='Data Sheet'!G28/'Data Sheet'!G$17 -> 0.19412329 | I22: ='Data Sheet'!H28/'Data Sheet'!H$17 -> 0.15591994 | J22: ='Data Sheet'!I28/'Data Sheet'!I$17 -> 0.16588158 | ... L22: ='Data Sheet'!K28/'Data Sheet'!K$17 -> 0.15765553
... B25: ='Data Sheet'!A31 -> Dividend Amount | C25: ='Data Sheet'!B31/'Data Sheet'!B$17 -> 0.025780941 | D25: ='Data Sheet'!C31/'Data Sheet'!C$17 -> 0.037634448 | E25: ='Data Sheet'!D31/'Data Sheet'!D$17 -> 0.048040107 | F25: ='Data Sheet'!E31/'Data Sheet'!E$17 -> 0.047928262 | G25: ='Data Sheet'!F31/'Data Sheet'!F$17 -> 0.059987013 | H25: ='Data Sheet'!G31/'Data Sheet'!G$17 -> 0.028473186 | I25: ='Data Sheet'!H31/'Data Sheet'!H$17 -> 0.053468919 | J25: ='Data Sheet'!I31/'Data Sheet'!I$17 -> 0.051162334 | ... L25: ='Data Sheet'!K31/'Data Sheet'!K$17 -> 0.042100185
B26: ='Data Sheet'!A34 -> EBITDA | C26: ='Data Sheet'!B34/'Data Sheet'!B$17 -> 0.24618025 | D26: ='Data Sheet'!C34/'Data Sheet'!C$17 -> 0.26943599 | E26: ='Data Sheet'!D34/'Data Sheet'!D$17 -> 0.28271619 | F26: ='Data Sheet'!E34/'Data Sheet'!E$17 -> 0.31905488 | G26: ='Data Sheet'!F34/'Data Sheet'!F$17 -> 0.25158331 | H26: ='Data Sheet'!G34/'Data Sheet'!G$17 -> 0.3607846 | I26: ='Data Sheet'!H34/'Data Sheet'!H$17 -> 0.34725438 | J26: ='Data Sheet'!I34/'Data Sheet'!I$17 -> 0.33833386 | ... L26: ='Data Sheet'!K34/'Data Sheet'!K$17 -> 0.31442551
B28: ="Common Size Balance Sheet" & " "& "-" & 'Data Sheet'!$B$1 -> Common Size Balance Sheet -NTPC LTD
B30: Particulars | C30: ='Data Sheet'!B57 -> 42094 | D30: ='Data Sheet'!C57 -> 42460 | E30: ='Data Sheet'!D57 -> 42825 | F30: ='Data Sheet'!E57 -> 43190 | G30: ='Data Sheet'!F57 -> 43555 | H30: ='Data Sheet'!G57 -> 43921 | I30: ='Data Sheet'!H57 -> 44286 | J30: ='Data Sheet'!I57 -> 44651 | ... L30: ='Data Sheet'!K57 -> 45382
B32: Total Liabilities | C32: ='Data Sheet'!B62/'Data Sheet'!B$62 -> 1 | D32: ='Data Sheet'!C62/'Data Sheet'!C$62 -> 1 | E32: ='Data Sheet'!D62/'Data Sheet'!D$62 -> 1 | F32: ='Data Sheet'!E62/'Data Sheet'!E$62 -> 1 | G32: ='Data Sheet'!F62/'Data Sheet'!F$62 -> 1 | H32: ='Data Sheet'!G62/'Data Sheet'!G$62 -> 1 | I32: ='Data Sheet'!H62/'Data Sheet'!H$62 -> 1 | J32: ='Data Sheet'!I62/'Data Sheet'!I$62 -> 1 | ... L32: ='Data Sheet'!K62/'Data Sheet'!K$62 -> 1
B33: ='Data Sheet'!A58 -> Equity Share Capital | C33: ='Data Sheet'!B58/'Data Sheet'!B$62 -> 0.037528485 | D33: ='Data Sheet'!C58/'Data Sheet'!C$62 -> 0.036701123 | E33: ='Data Sheet'!D58/'Data Sheet'!D$62 -> 0.033167469 | F33: ='Data Sheet'!E58/'Data Sheet'!E$62 -> 0.029188269 | G33: ='Data Sheet'!F58/'Data Sheet'!F$62 -> 0.028520912 | H33: ='Data Sheet'!G58/'Data Sheet'!G$62 -> 0.026205965 | I33: ='Data Sheet'!H58/'Data Sheet'!H$62 -> 0.024362159 | J33: ='Data Sheet'!I58/'Data Sheet'!I$62 -> 0.023318753 | ... L33: ='Data Sheet'!K58/'Data Sheet'!K$62 -> 0.02023184
B34: ='Data Sheet'!A59 -> Reserves | C34: ='Data Sheet'!B59/'Data Sheet'!B$62 -> 0.33611503 | D34: ='Data Sheet'!C59/'Data Sheet'!C$62 -> 0.37090823 | E34: ='Data Sheet'!D59/'Data Sheet'!D$62 -> 0.36038723 | F34: ='Data Sheet'!E59/'Data Sheet'!E$62 -> 0.33741813 | G34: ='Data Sheet'!F59/'Data Sheet'!F$62 -> 0.29246159 | H34: ='Data Sheet'!G59/'Data Sheet'!G$62 -> 0.28854223 | I34: ='Data Sheet'!H59/'Data Sheet'!H$62 -> 0.29154635 | J34: ='Data Sheet'!I59/'Data Sheet'!I$62 -> 0.30223082 | ... L34: ='Data Sheet'!K59/'Data Sheet'!K$62 -> 0.31508371
B35: ='Data Sheet'!A60 -> Borrowings | C35: ='Data Sheet'!B60/'Data Sheet'!B$62 -> 0.46539097 | D35: ='Data Sheet'!C60/'Data Sheet'!C$62 -> 0.44254122 | E35: ='Data Sheet'!D60/'Data Sheet'!D$62 -> 0.45765416 | F35: ='Data Sheet'!E60/'Data Sheet'!E$62 -> 0.4603615 | G35: ='Data Sheet'!F60/'Data Sheet'!F$62 -> 0.4988376 | H35: ='Data Sheet'!G60/'Data Sheet'!G$62 -> 0.53760852 | I35: ='Data Sheet'!H60/'Data Sheet'!H$62 -> 0.52813156 | J35: ='Data Sheet'!I60/'Data Sheet'!I$62 -> 0.50671149 | ... L35: ='Data Sheet'!K60/'Data Sheet'!K$62 -> 0.49476738
B36: ='Data Sheet'!A61 -> Other Liabilities | C36: ='Data Sheet'!B61/'Data Sheet'!B$62 -> 0.16096551 | D36: ='Data Sheet'!C61/'Data Sheet'!C$62 -> 0.14984942 | E36: ='Data Sheet'!D61/'Data Sheet'!D$62 -> 0.14879114 | F36: ='Data Sheet'!E61/'Data Sheet'!E$62 -> 0.1730321 | G36: ='Data Sheet'!F61/'Data Sheet'!F$62 -> 0.1801799 | H36: ='Data Sheet'!G61/'Data Sheet'!G$62 -> 0.14764329 | I36: ='Data Sheet'!H61/'Data Sheet'!H$62 -> 0.15595993 | J36: ='Data Sheet'!I61/'Data Sheet'!I$62 -> 0.16773894 | ... L36: ='Data Sheet'!K61/'Data Sheet'!K$62 -> 0.16991708
B38: Total Assets | C38: ='Data Sheet'!B76/'Data Sheet'!B$76 -> 1 | D38: ='Data Sheet'!C76/'Data Sheet'!C$76 -> 1 | E38: ='Data Sheet'!D76/'Data Sheet'!D$76 -> 1 | F38: ='Data Sheet'!E76/'Data Sheet'!E$76 -> 1 | G38: ='Data Sheet'!F76/'Data Sheet'!F$76 -> 1 | H38: ='Data Sheet'!G76/'Data Sheet'!G$76 -> 1 | I38: ='Data Sheet'!H76/'Data Sheet'!H$76 -> 1 | J38: ='Data Sheet'!I76/'Data Sheet'!I$76 -> 1 | ... L38: ='Data Sheet'!K76/'Data Sheet'!K$76 -> 1
B39: ='Data Sheet'!A63 -> Net Block | C39: ='Data Sheet'!B63/'Data Sheet'!B$76 -> 0.41806093 | D39: ='Data Sheet'!C63/'Data Sheet'!C$76 -> 0.41363512 | E39: ='Data Sheet'!D63/'Data Sheet'!D$76 -> 0.42047995 | F39: ='Data Sheet'!E63/'Data Sheet'!E$76 -> 0.45397853 | G39: ='Data Sheet'!F63/'Data Sheet'!F$76 -> 0.43521051 | H39: ='Data Sheet'!G63/'Data Sheet'!G$76 -> 0.49739992 | I39: ='Data Sheet'!H63/'Data Sheet'!H$76 -> 0.51063832 | J39: ='Data Sheet'!I63/'Data Sheet'!I$76 -> 0.54089953 | ... L39: ='Data Sheet'!K63/'Data Sheet'!K$76 -> 0.54025802
B40: ='Data Sheet'!A64 -> Capital Work in Progress | C40: ='Data Sheet'!B64/'Data Sheet'!B$76 -> 0.30746922 | D40: ='Data Sheet'!C64/'Data Sheet'!C$76 -> 0.33403294 | E40: ='Data Sheet'!D64/'Data Sheet'!D$76 -> 0.34953911 | F40: ='Data Sheet'!E64/'Data Sheet'!E$76 -> 0.29518012 | G40: ='Data Sheet'!F64/'Data Sheet'!F$76 -> 0.34127707 | H40: ='Data Sheet'!G64/'Data Sheet'!G$76 -> 0.2609019 | I40: ='Data Sheet'!H64/'Data Sheet'!H$76 -> 0.24497661 | J40: ='Data Sheet'!I64/'Data Sheet'!I$76 -> 0.21914231 | ... L40: ='Data Sheet'!K64/'Data Sheet'!K$76 -> 0.1829095
B41: ='Data Sheet'!A65 -> Investments | C41: ='Data Sheet'!B65/'Data Sheet'!B$76 -> 0.0086545553 | D41: ='Data Sheet'!C65/'Data Sheet'!C$76 -> 0.028813381 | E41: ='Data Sheet'!D65/'Data Sheet'!D$76 -> 0.030627091 | F41: ='Data Sheet'!E65/'Data Sheet'!E$76 -> 0.031418949 | G41: ='Data Sheet'!F65/'Data Sheet'!F$76 -> 0.023441254 | H41: ='Data Sheet'!G65/'Data Sheet'!G$76 -> 0.024648713 | I41: ='Data Sheet'!H65/'Data Sheet'!H$76 -> 0.026604699 | J41: ='Data Sheet'!I65/'Data Sheet'!I$76 -> 0.025554202 | ... L41: ='Data Sheet'!K65/'Data Sheet'!K$76 -> 0.033142705
B42: ='Data Sheet'!A66 -> Other Assets | C42: ='Data Sheet'!B75/'Data Sheet'!B$76 -> 0.12216713 | D42: ='Data Sheet'!C75/'Data Sheet'!C$76 -> 0.13284286 | E42: ='Data Sheet'!D75/'Data Sheet'!D$76 -> 0.12310736 | F42: ='Data Sheet'!E75/'Data Sheet'!E$76 -> 0.15049779 | G42: ='Data Sheet'!F75/'Data Sheet'!F$76 -> 0.13143808 | H42: ='Data Sheet'!G75/'Data Sheet'!G$76 -> 0.12475487 | I42: ='Data Sheet'!H75/'Data Sheet'!H$76 -> 0.11073278 | J42: ='Data Sheet'!I75/'Data Sheet'!I$76 -> 0.11148015 | ... L42: ='Data Sheet'!K75/'Data Sheet'!K$76 -> 0.12169956
B43: ='Data Sheet'!A68 -> Receivables | C43: ='Data Sheet'!B68/'Data Sheet'!B$76 -> 0.042100196 | D43: ='Data Sheet'!C68/'Data Sheet'!C$76 -> 0.036893988 | E43: ='Data Sheet'!D68/'Data Sheet'!D$76 -> 0.036057363 | F43: ='Data Sheet'!E68/'Data Sheet'!E$76 -> 0.031194448 | G43: ='Data Sheet'!F68/'Data Sheet'!F$76 -> 0.03563765 | H43: ='Data Sheet'!G68/'Data Sheet'!G$76 -> 0.053803649 | I43: ='Data Sheet'!H68/'Data Sheet'!H$76 -> 0.070849965 | J43: ='Data Sheet'!I68/'Data Sheet'!I$76 -> 0.067264927 | ... L43: ='Data Sheet'!K68/'Data Sheet'!K$76 -> 0.069583205
B44: ='Data Sheet'!A69 -> Inventory | C44: ='Data Sheet'!B69/'Data Sheet'!B$76 -> 0.036683015 | D44: ='Data Sheet'!C69/'Data Sheet'!C$76 -> 0.031800895 | E44: ='Data Sheet'!D69/'Data Sheet'!D$76 -> 0.026908962 | F44: ='Data Sheet'!E69/'Data Sheet'!E$76 -> 0.022198414 | G44: ='Data Sheet'!F69/'Data Sheet'!F$76 -> 0.024539884 | H44: ='Data Sheet'!G69/'Data Sheet'!G$76 -> 0.029977832 | I44: ='Data Sheet'!H69/'Data Sheet'!H$76 -> 0.025173597 | J44: ='Data Sheet'!I69/'Data Sheet'!I$76 -> 0.02493799 | ... L44: ='Data Sheet'!K69/'Data Sheet'!K$76 -> 0.038120216
B45: ='Data Sheet'!A70 -> Cash & Bank | C45: ='Data Sheet'!B70/'Data Sheet'!B$76 -> 0.064864948 | D45: ='Data Sheet'!C70/'Data Sheet'!C$76 -> 0.02198081 | E45: ='Data Sheet'!D70/'Data Sheet'!D$76 -> 0.013280165 | F45: ='Data Sheet'!E70/'Data Sheet'!E$76 -> 0.015531753 | G45: ='Data Sheet'!F70/'Data Sheet'!F$76 -> 0.0084555653 | H45: ='Data Sheet'!G70/'Data Sheet'!G$76 -> 0.0085131195 | I45: ='Data Sheet'!H70/'Data Sheet'!H$76 -> 0.01102402 | J45: ='Data Sheet'!I70/'Data Sheet'!I$76 -> 0.010720883 | ... L45: ='Data Sheet'!K70/'Data Sheet'!K$76 -> 0.01428679

Sheet Ratio Analysis
B3: =B7 -> Ratio Analysis - NTPC LTD
B7: ="Ratio Analysis - " & 'Data Sheet'!B1 -> Ratio Analysis - NTPC LTD
B8: Years | C8: ='Data Sheet'!B57 -> 42094 | D8: ='Data Sheet'!C57 -> 42460 | E8: ='Data Sheet'!D57 -> 42825 | F8: ='Data Sheet'!E57 -> 43190 | G8: ='Data Sheet'!F57 -> 43555 | H8: ='Data Sheet'!G57 -> 43921 | I8: ='Data Sheet'!H57 -> 44286 | J8: ='Data Sheet'!I57 -> 44651 | ... L8: ='Data Sheet'!K57 -> 45382 | M8: Trend | N8: Median | O8: Mean
B10: SalesGrowth | C10: - | D10: =IFERROR(HistoricalFS!D11,0) -> -0.082049618 | E10: =IFERROR(HistoricalFS!E11,0) -> 0.11780114 | F10: =IFERROR(HistoricalFS!F11,0) -> 0.073630383 | G10: =IFERROR(HistoricalFS!G11,0) -> 0.13854191 | H10: =IFERROR(HistoricalFS!H11,0) -> 0.091512779 | I10: =IFERROR(HistoricalFS!I11,0) -> 0.018883918 | J10: =IFERROR(HistoricalFS!J11,0) -> 0.18952669 | K10: =IFERROR(HistoricalFS!K11,0) -> 0.32816866 | L10: =IFERROR(HistoricalFS!L11,0) -> 0.013017063 | N10: =IFERROR(AVERAGE(D10:L10),0) -> 0.098781436 | O10: =IFERROR(MEDIAN(C10:L10),0) -> 0.091512779
B11: EBITDA growth | C11: - | D11: =IFERROR(HistoricalFS!D22/HistoricalFS!C22-1,0) -> 0.070042162 | E11: =IFERROR(HistoricalFS!E22/HistoricalFS!D22-1,0) -> 0.16318998 | F11: =IFERROR(HistoricalFS!F22/HistoricalFS!E22-1,0) -> 0.041110257 | G11: =IFERROR(HistoricalFS!G22/HistoricalFS!F22-1,0) -> 0.01000471 | H11: =IFERROR(HistoricalFS!H22/HistoricalFS!G22-1,0) -> 0.39080649 | I11: =IFERROR(HistoricalFS!I22/HistoricalFS!H22-1,0) -> 0.077819636 | J11: =IFERROR(HistoricalFS!J22/HistoricalFS!I22-1,0) -> 0.18559076 | K11: =IFERROR(HistoricalFS!K22/HistoricalFS!J22-1,0) -> 0.17922909 | L11: =IFERROR(HistoricalFS!L22/HistoricalFS!K22-1,0) -> 0.081093875 | N11: =IFERROR(AVERAGE(D11:L11),0) -> 0.13320966 | O11: =IFERROR(MEDIAN(C11:L11),0) -> 0.081093875
B12: EBIT Growth | C12: - | D12: =IFERROR(HistoricalFS!D31/HistoricalFS!C31-1,0) -> 0.16156866 | E12: =IFERROR(HistoricalFS!E31/HistoricalFS!D31-1,0) -> 0.25498742 | F12: =IFERROR(HistoricalFS!F31/HistoricalFS!E31-1,0) -> -0.1061216 | G12: =IFERROR(HistoricalFS!G31/HistoricalFS!F31-1,0) -> -0.20249762 | H12: =IFERROR(HistoricalFS!H31/HistoricalFS!G31-1,0) -> 0.54569624 | I12: =IFERROR(HistoricalFS!I31/HistoricalFS!H31-1,0) -> -0.051482452 | J12: =IFERROR(HistoricalFS!J31/HistoricalFS!I31-1,0) -> 0.39042218 | K12: =IFERROR(HistoricalFS!K31/HistoricalFS!J31-1,0) -> 0.24177351 | L12: =IFERROR(HistoricalFS!L31/HistoricalFS!K31-1,0) -> 0.074685354 | N12: =IFERROR(AVERAGE(D12:L12),0) -> 0.14544797 | O12: =IFERROR(MEDIAN(C12:L12),0) -> 0.16156866
B13: Net Profit Growth | C13: - | D13: =IFERROR(HistoricalFS!D37/HistoricalFS!C37-1,0) -> 0.25322384 | E13: =IFERROR(HistoricalFS!E37/HistoricalFS!D37-1,0) -> -0.049057442 | F13: =IFERROR(HistoricalFS!F37/HistoricalFS!E37-1,0) -> -0.46001778 | G13: =IFERROR(HistoricalFS!G37/HistoricalFS!F37-1,0) -> 1.2770491 | H13: =IFERROR(HistoricalFS!H37/HistoricalFS!G37-1,0) -> -0.67075494 | I13: =IFERROR(HistoricalFS!I37/HistoricalFS!H37-1,0) -> 1.6939118 | J13: =IFERROR(HistoricalFS!J37/HistoricalFS!I37-1,0) -> 0.22140045 | K13: =IFERROR(HistoricalFS!K37/HistoricalFS!J37-1,0) -> 0.19825846 | L13: =IFERROR(HistoricalFS!L37/HistoricalFS!K37-1,0) -> 0.10864667 | N13: =IFERROR(AVERAGE(D13:L13),0) -> 0.28585112 | O13: =IFERROR(AVERAGE(E13:M13),0) -> 0.28992953
B14: Dividend Growth | C14: - | D14: =IFERROR(HistoricalFS!D45/HistoricalFS!C45-1,0) -> 0.34000369 | E14: =IFERROR(HistoricalFS!E45/HistoricalFS!D45-1,0) -> 0.42686525 | F14: =IFERROR(HistoricalFS!F45/HistoricalFS!E45-1,0) -> 0.071130811 | G14: =IFERROR(HistoricalFS!G45/HistoricalFS!F45-1,0) -> 0.42499905 | H14: =IFERROR(HistoricalFS!H45/HistoricalFS!G45-1,0) -> -0.48190708 | I14: =IFERROR(HistoricalFS!I45/HistoricalFS!H45-1,0) -> 0.95237988 | J14: =IFERROR(HistoricalFS!J45/HistoricalFS!I45-1,0) -> 0.13821194 | K14: =IFERROR(HistoricalFS!K45/HistoricalFS!J45-1,0) -> 0.035714759 | L14: =IFERROR(HistoricalFS!L45/HistoricalFS!K45-1,0) -> 0.068964978 | N14: =IFERROR(AVERAGE(D14:L14),0) -> 0.21959592 | O14: =IFERROR(AVERAGE(E14:M14),0) -> 0.20454495
B16: Gross Margin | C16: =IFERROR(HistoricalFS!C17,0) -> 0.21857344 | D16: =IFERROR(HistoricalFS!D17,0) -> 0.25538256 | E16: =IFERROR(HistoricalFS!E17,0) -> 0.2643184 | F16: =IFERROR(HistoricalFS!F17,0) -> 0.26903088 | G16: =IFERROR(HistoricalFS!G17,0) -> 0.27969207 | H16: =IFERROR(HistoricalFS!H17,0) -> 0.30917934 | I16: =IFERROR(HistoricalFS!I17,0) -> 0.32654115 | J16: =IFERROR(HistoricalFS!J17,0) -> 0.31238196 | ... L16: =IFERROR(HistoricalFS!L17,0) -> 0.29324113 | N16: =IFERROR(AVERAGE(C16:L16),0) -> 0.28190915 | O16: =IFERROR(MEDIAN(C16:L16),0) -> 0.28522133
B17: EBITDA Margin | C17: =IFERROR(HistoricalFS!C23,0) -> 0.21701885 | D17: =IFERROR(HistoricalFS!D23,0) -> 0.2529759 | E17: =IFERROR(HistoricalFS!E23,0) -> 0.2632481 | F17: =IFERROR(HistoricalFS!F23,0) -> 0.25527435 | G17: =IFERROR(HistoricalFS!G23,0) -> 0.22645482 | H17: =IFERROR(HistoricalFS!H23,0) -> 0.28854892 | I17: =IFERROR(HistoricalFS!I23,0) -> 0.30523957 | J17: =IFERROR(HistoricalFS!J23,0) -> 0.30422959 | ... L17: =IFERROR(HistoricalFS!L23,0) -> 0.28826575 | N17: =IFERROR(AVERAGE(C17:L17),0) -> 0.26713694 | O17: =IFERROR(MEDIAN(C17:L17),0) -> 0.26668084
B18: EBIT Margin | C18: =IFERROR((HistoricalFS!C22-HistoricalFS!C28)/HistoricalFS!C10,0) -> 0.14742359 | D18: =IFERROR((HistoricalFS!D22-HistoricalFS!D28)/HistoricalFS!D10,0) -> 0.17434471 | E18: =IFERROR((HistoricalFS!E22-HistoricalFS!E28)/HistoricalFS!E10,0) -> 0.18999448 | F18: =IFERROR((HistoricalFS!F22-HistoricalFS!F28)/HistoricalFS!F10,0) -> 0.1705826 | G18: =IFERROR((HistoricalFS!G22-HistoricalFS!G28)/HistoricalFS!G10,0) -> 0.14001221 | H18: =IFERROR((HistoricalFS!H22-HistoricalFS!H28)/HistoricalFS!H10,0) -> 0.19394104 | I18: =IFERROR((HistoricalFS!I22-HistoricalFS!I28)/HistoricalFS!I10,0) -> 0.19360878 | J18: =IFERROR((HistoricalFS!J22-HistoricalFS!J28)/HistoricalFS!J10,0) -> 0.20030327 | ... L18: =IFERROR((HistoricalFS!L22-HistoricalFS!L28)/HistoricalFS!L10,0) -> 0.19748956 | N18: =IFERROR(AVERAGE(C18:L18),0) -> 0.17938656 | O18: =IFERROR(MEDIAN(C18:L18),0) -> 0.18807994
B19: EBT Margin | C19: =IFERROR(HistoricalFS!C32,0) -> 0.10153653 | D19: =IFERROR(HistoricalFS!D32,0) -> 0.12848369 | E19: =IFERROR(HistoricalFS!E32,0) -> 0.14425233 | F19: =IFERROR(HistoricalFS!F32,0) -> 0.12010096 | G19: =IFERROR(HistoricalFS!G32,0) -> 0.084125846 | H19: =IFERROR(HistoricalFS!H32,0) -> 0.11913099 | I19: =IFERROR(HistoricalFS!I32,0) -> 0.11090355 | J19: =IFERROR(HistoricalFS!J32,0) -> 0.1296337 | ... L19: =IFERROR(HistoricalFS!L32,0) -> 0.12857948 | N19: =IFERROR(AVERAGE(C19:L19),0) -> 0.11879483 | O19: =IFERROR(MEDIAN(C19:L19),0) -> 0.1206511
B20: Net Profit Margin | C20: =IFERROR(HistoricalFS!C38,0) -> 0.095735394 | D20: =IFERROR(HistoricalFS!D38,0) -> 0.13070192 | E20: =IFERROR(HistoricalFS!E38,0) -> 0.11119153 | F20: =IFERROR(HistoricalFS!F38,0) -> 0.055923761 | G20: =IFERROR(HistoricalFS!G38,0) -> 0.11184582 | H20: =IFERROR(HistoricalFS!H38,0) -> 0.033737289 | I20: =IFERROR(HistoricalFS!I38,0) -> 0.08920082 | J20: =IFERROR(HistoricalFS!J38,0) -> 0.091590985 | ... L20: =IFERROR(HistoricalFS!L38,0) -> 0.090432888 | N20: =IFERROR(AVERAGE(C20:L20),0) -> 0.089299274 | O20: =IFERROR(MEDIAN(C20:L20),0) -> 0.091011936
B22: Sales Expenses % Sales | C22: =IFERROR(HistoricalFS!C20,0) -> 0.0015545906 | D22: =IFERROR(HistoricalFS!D20,0) -> 0.0024066602 | E22: =IFERROR(HistoricalFS!E20,0) -> 0.0010702991 | F22: =IFERROR(HistoricalFS!F20,0) -> 0.013756522 | G22: =IFERROR(HistoricalFS!G20,0) -> 0.053237254 | H22: =IFERROR(HistoricalFS!H20,0) -> 0.020630428 | I22: =IFERROR(HistoricalFS!I20,0) -> 0.021301583 | J22: =IFERROR(HistoricalFS!J20,0) -> 0.0081523771 | ... L22: =IFERROR(HistoricalFS!L20,0) -> 0.0049753816 | N22: =IFERROR(AVERAGE(C22:L22),0) -> 0.014772211 | O22: =IFERROR(MEDIAN(C22:L22),0) -> 0.01095445
B23: Depericiation % sales | C23: =IFERROR(HistoricalFS!C29,0) -> 0.069595259 | D23: =IFERROR(HistoricalFS!D29,0) -> 0.07863119 | E23: =IFERROR(HistoricalFS!E29,0) -> 0.073253627 | F23: =IFERROR(HistoricalFS!F29,0) -> 0.084691754 | G23: =IFERROR(HistoricalFS!G29,0) -> 0.086442607 | H23: =IFERROR(HistoricalFS!H29,0) -> 0.094607873 | I23: =IFERROR(HistoricalFS!I29,0) -> 0.11163079 | J23: =IFERROR(HistoricalFS!J29,0) -> 0.10392632 | ... L23: =IFERROR(HistoricalFS!L29,0) -> 0.090776191 | N23: =IFERROR(AVERAGE(C23:L23),0) -> 0.087750378 | O23: =IFERROR(MEDIAN(C23:L23),0) -> 0.085567181
B24: Operating Income % Sales | C24: =C18 -> 0.14742359 | D24: =D18 -> 0.17434471 | E24: =E18 -> 0.18999448 | F24: =F18 -> 0.1705826 | G24: =G18 -> 0.14001221 | H24: =H18 -> 0.19394104 | I24: =I18 -> 0.19360878 | J24: =J18 -> 0.20030327 | ... L24: =L18 -> 0.19748956 | N24: =IFERROR(AVERAGE(C24:L24),0) -> 0.17938656 | O24: =IFERROR(MEDIAN(C24:L24),0) -> 0.18807994
B26: Return on Capital Employed | C26: =IFERROR((HistoricalFS!C22-HistoricalFS!C28)/(SUM(HistoricalFS!C54:C56)),0) -> 0.063942322 | D26: =IFERROR((HistoricalFS!D22-HistoricalFS!D28)/(SUM(HistoricalFS!D54:D56)),0) -> 0.066996431 | E26: =IFERROR((HistoricalFS!E22-HistoricalFS!E28)/(SUM(HistoricalFS!E54:E56)),0) -> 0.073661595 | F26: =IFERROR((HistoricalFS!F22-HistoricalFS!F28)/(SUM(HistoricalFS!F54:F56)),0) -> 0.064318092 | G26: =IFERROR((HistoricalFS!G22-HistoricalFS!G28)/(SUM(HistoricalFS!G54:G56)),0) -> 0.049369294 | H26: =IFERROR((HistoricalFS!H22-HistoricalFS!H28)/(SUM(HistoricalFS!H54:H56)),0) -> 0.065966506 | I26: =IFERROR((HistoricalFS!I22-HistoricalFS!I28)/(SUM(HistoricalFS!I54:I56)),0) -> 0.064276366 | J26: =IFERROR((HistoricalFS!J22-HistoricalFS!J28)/(SUM(HistoricalFS!J54:J56)),0) -> 0.076785908 | ... L26: =IFERROR((HistoricalFS!L22-HistoricalFS!L28)/(SUM(HistoricalFS!L54:L56)),0) -> 0.088608581 | N26: =IFERROR(AVERAGE(C26:L26),0) -> 0.070259895 | O26: =IFERROR(MEDIAN(C26:L26),0) -> 0.066481469
B27: Retained Earnings% | C27: =IFERROR(HistoricalFS!C48,0) -> 0.73070627 | D27: =IFERROR(HistoricalFS!D48,0) -> 0.71205895 | E27: =IFERROR(HistoricalFS!E48,0) -> 0.56795174 | F27: =IFERROR(HistoricalFS!F48,0) -> 0.14297141 | G27: =IFERROR(HistoricalFS!G48,0) -> 0.46366333 | H27: =IFERROR(HistoricalFS!H48,0) -> 0.15603219 | I27: =IFERROR(HistoricalFS!I48,0) -> 0.40057817 | J27: =IFERROR(HistoricalFS!J48,0) -> 0.44140426 | ... L27: =IFERROR(HistoricalFS!L48,0) -> 0.53445936 | N27: =IFERROR(AVERAGE(C27:L27),0) -> 0.46670034 | O27: =IFERROR(MEDIAN(C27:L27),0) -> 0.49042054
B28: Return on Equity % | C28: =IFERROR(HistoricalFS!C37/SUM(HistoricalFS!C54:C55),0) -> 0.093243012 | D28: =IFERROR(HistoricalFS!D37/SUM(HistoricalFS!D54:D55),0) -> 0.10475544 | E28: =IFERROR(HistoricalFS!E37/SUM(HistoricalFS!E54:E55),0) -> 0.093240133 | F28: =IFERROR(HistoricalFS!F37/SUM(HistoricalFS!F54:F55),0) -> 0.047564551 | G28: =IFERROR(HistoricalFS!G37/SUM(HistoricalFS!G54:G55),0) -> 0.10072748 | H28: =IFERROR(HistoricalFS!H37/SUM(HistoricalFS!H54:H55),0) -> 0.031075783 | I28: =IFERROR(HistoricalFS!I37/SUM(HistoricalFS!I54:I55),0) -> 0.079121927 | J28: =IFERROR(HistoricalFS!J37/SUM(HistoricalFS!J54:J55),0) -> 0.089761205 | ... L28: =IFERROR(HistoricalFS!L37/SUM(HistoricalFS!L54:L55),0) -> 0.10044442 | N28: =IFERROR(AVERAGE(C28:L28),0) -> 0.083896875 | O28: =IFERROR(MEDIAN(C28:L28),0) -> 0.093241573
B29: Self Sustainedd Growth Rate | C29: =IFERROR(C27*C28,0) -> 0.068133254 | D29: =IFERROR(D27*D28,0) -> 0.074592047 | E29: =IFERROR(E27*E28,0) -> 0.052955896 | F29: =IFERROR(F27*F28,0) -> 0.0068003708 | G29: =IFERROR(G27*G28,0) -> 0.046703637 | H29: =IFERROR(H27*H28,0) -> 0.0048488226 | I29: =IFERROR(I27*I28,0) -> 0.031694516 | J29: =IFERROR(J27*J28,0) -> 0.039620978 | ... L29: =IFERROR(L27*L28,0) -> 0.053683462 | N29: =IFERROR(AVERAGE(C29:L29),0) -> 0.043025158 | O29: =IFERROR(MEDIAN(C29:L29),0) -> 0.048961115
B30: Interst Coverage Ratio | C30: =IFERROR((HistoricalFS!C22-HistoricalFS!C28)/HistoricalFS!C25,0) -> 3.2127485 | D30: =IFERROR((HistoricalFS!D22-HistoricalFS!D28)/HistoricalFS!D25,0) -> 3.8015882 | E30: =IFERROR((HistoricalFS!E22-HistoricalFS!E28)/HistoricalFS!E25,0) -> 4.1535973 | F30: =IFERROR((HistoricalFS!F22-HistoricalFS!F28)/HistoricalFS!F25,0) -> 3.3791017 | G30: =IFERROR((HistoricalFS!G22-HistoricalFS!G28)/HistoricalFS!G25,0) -> 2.5053018 | H30: =IFERROR((HistoricalFS!H22-HistoricalFS!H28)/HistoricalFS!H25,0) -> 2.5924465 | I30: =IFERROR((HistoricalFS!I22-HistoricalFS!I28)/HistoricalFS!I25,0) -> 2.3409495 | J30: =IFERROR((HistoricalFS!J22-HistoricalFS!J28)/HistoricalFS!J25,0) -> 2.834364 | ... L30: =IFERROR((HistoricalFS!L22-HistoricalFS!L28)/HistoricalFS!L25,0) -> 2.8659023 | N30: =IFERROR(AVERAGE(C30:L30),0) -> 3.0551663 | O30: =IFERROR(MEDIAN(C30:L30),0) -> 2.8657829
B32: Debtor Turnover Ratio | C32: =HistoricalFS!C10/HistoricalFS!C78 -> -25.151538 | D32: =HistoricalFS!D10/HistoricalFS!D78 -> -33.016788 | E32: =HistoricalFS!E10/HistoricalFS!E78 -> -19.759752 | F32: =HistoricalFS!F10/HistoricalFS!F78 -> -8.2413277 | G32: =HistoricalFS!G10/HistoricalFS!G78 -> -11.00961 | H32: =HistoricalFS!H10/HistoricalFS!H78 -> 11.001411 | I32: =HistoricalFS!I10/HistoricalFS!I78 -> -20.259973 | J32: =HistoricalFS!J10/HistoricalFS!J78 -> 717.13124 | ... L32: =HistoricalFS!L10/HistoricalFS!L78 -> -95.200469 | N32: =IFERROR(AVERAGE(C32:L32),0) -> 43.586953 | O32: =IFERROR(MEDIAN(C32:L32),0) -> -20.009862
B33: Creditor Turnover Ratio | C33: =IFERROR(HistoricalFS!C10/HistoricalFS!C57,0) -> 2.2608326 | D33: =IFERROR(HistoricalFS!D10/HistoricalFS!D57,0) -> 2.1801364 | E33: =IFERROR(HistoricalFS!E10/HistoricalFS!E57,0) -> 2.217988 | F33: =IFERROR(HistoricalFS!F10/HistoricalFS!F57,0) -> 1.8020232 | G33: =IFERROR(HistoricalFS!G10/HistoricalFS!G57,0) -> 1.6043652 | H33: =IFERROR(HistoricalFS!H10/HistoricalFS!H57,0) -> 1.963638 | I33: =IFERROR(HistoricalFS!I10/HistoricalFS!I57,0) -> 1.796703 | J33: =IFERROR(HistoricalFS!J10/HistoricalFS!J57,0) -> 1.902038 | ... L33: =IFERROR(HistoricalFS!L10/HistoricalFS!L57,0) -> 2.1918765 | N33: =IFERROR(AVERAGE(C33:L33),0) -> 2.0200524 | O33: =IFERROR(MEDIAN(C33:L33),0) -> 2.0718872
B34: Inventory Turnover Ratio | C34: =IFERROR(HistoricalFS!C10/HistoricalFS!C67,0) -> 9.9205603 | D34: =IFERROR(HistoricalFS!D10/HistoricalFS!D67,0) -> 10.27305 | E34: =IFERROR(HistoricalFS!E10/HistoricalFS!E67,0) -> 12.264203 | F34: =IFERROR(HistoricalFS!F10/HistoricalFS!F67,0) -> 14.046403 | G34: =IFERROR(HistoricalFS!G10/HistoricalFS!G67,0) -> 11.779777 | H34: =IFERROR(HistoricalFS!H10/HistoricalFS!H67,0) -> 9.6710788 | I34: =IFERROR(HistoricalFS!I10/HistoricalFS!I67,0) -> 11.131253 | J34: =IFERROR(HistoricalFS!J10/HistoricalFS!J67,0) -> 12.793566 | ... L34: =IFERROR(HistoricalFS!L10/HistoricalFS!L67,0) -> 9.7700722 | N34: =IFERROR(AVERAGE(C34:L34),0) -> 11.384098 | O34: =IFERROR(MEDIAN(C34:L34),0) -> 11.455515
